{
 "cells": [
  {
   "cell_type": "markdown",
   "id": "f45cabc7",
   "metadata": {},
   "source": [
    "# Problem Statement\n",
    "Currently the latest AWS Deep Learning Container (DLC) for Hugging Face's `transformers` library supports version 4.17.0 while, at time of writing (29 Nov 2022), the latest publicly available version of `transformers` is 4.24.0\n",
    "\n",
    "This matters because newer models like BLOOM and Whisper will require a version of `transformers` greater than 4.17.0. See below what happens if we try to deploy the BLOOM model directly from the Hugging Face Model Hub into the latest DLC."
   ]
  },
  {
   "cell_type": "code",
   "execution_count": 1,
   "id": "d94507f9",
   "metadata": {},
   "outputs": [],
   "source": [
    "from sagemaker.huggingface import HuggingFaceModel\n",
    "import sagemaker\n",
    "\n",
    "role = sagemaker.get_execution_role()"
   ]
  },
  {
   "cell_type": "markdown",
   "id": "9d54c61c",
   "metadata": {},
   "source": [
    "We use the [BLOOM-560M](https://huggingface.co/bigscience/bloom-560m) model to test the DLC"
   ]
  },
  {
   "cell_type": "code",
   "execution_count": 2,
   "id": "3a5807d5",
   "metadata": {},
   "outputs": [],
   "source": [
    "hub = {\n",
    "    'HF_MODEL_ID':'bigscience/bloom-560m',\n",
    "    'HF_TASK':'text-generation'\n",
    "}"
   ]
  },
  {
   "cell_type": "code",
   "execution_count": 3,
   "id": "72f11d3f",
   "metadata": {},
   "outputs": [],
   "source": [
    "huggingface_model = HuggingFaceModel(\n",
    "    env=hub,\n",
    "    role=role,\n",
    "    transformers_version=\"4.17\",\n",
    "    pytorch_version=\"1.10\",\n",
    "    py_version=\"py38\",\n",
    ")"
   ]
  },
  {
   "cell_type": "code",
   "execution_count": 4,
   "id": "0facd8dd",
   "metadata": {},
   "outputs": [
    {
     "name": "stdout",
     "output_type": "stream",
     "text": [
      "--------!"
     ]
    }
   ],
   "source": [
    "predictor = huggingface_model.deploy(\n",
    "    initial_instance_count=1,\n",
    "    instance_type=\"ml.g4dn.xlarge\"\n",
    ")"
   ]
  },
  {
   "cell_type": "markdown",
   "id": "5f99e177",
   "metadata": {},
   "source": [
    "The model deployed just fine and we have a running endpoint. However, when we try to send an inference request, we get an error:"
   ]
  },
  {
   "cell_type": "code",
   "execution_count": 5,
   "id": "804e92f5",
   "metadata": {},
   "outputs": [
    {
     "ename": "ModelError",
     "evalue": "An error occurred (ModelError) when calling the InvokeEndpoint operation: Received client error (400) from primary with message \"{\n  \"code\": 400,\n  \"type\": \"InternalServerException\",\n  \"message\": \"\\u0027bloom\\u0027\"\n}\n\". See https://us-east-1.console.aws.amazon.com/cloudwatch/home?region=us-east-1#logEventViewer:group=/aws/sagemaker/Endpoints/huggingface-pytorch-inference-2022-11-10-12-26-04-489 in account 905847418383 for more information.",
     "output_type": "error",
     "traceback": [
      "\u001b[0;31m---------------------------------------------------------------------------\u001b[0m",
      "\u001b[0;31mModelError\u001b[0m                                Traceback (most recent call last)",
      "\u001b[0;32m/tmp/ipykernel_2468/3981811068.py\u001b[0m in \u001b[0;36m<cell line: 3>\u001b[0;34m()\u001b[0m\n\u001b[1;32m      1\u001b[0m \u001b[0mdata\u001b[0m \u001b[0;34m=\u001b[0m \u001b[0;34m{\u001b[0m\u001b[0;34m\"inputs\"\u001b[0m\u001b[0;34m:\u001b[0m \u001b[0;34m\"And this is where the problem lies\"\u001b[0m\u001b[0;34m}\u001b[0m\u001b[0;34m\u001b[0m\u001b[0;34m\u001b[0m\u001b[0m\n\u001b[1;32m      2\u001b[0m \u001b[0;34m\u001b[0m\u001b[0m\n\u001b[0;32m----> 3\u001b[0;31m \u001b[0mpredictor\u001b[0m\u001b[0;34m.\u001b[0m\u001b[0mpredict\u001b[0m\u001b[0;34m(\u001b[0m\u001b[0mdata\u001b[0m\u001b[0;34m)\u001b[0m\u001b[0;34m\u001b[0m\u001b[0;34m\u001b[0m\u001b[0m\n\u001b[0m",
      "\u001b[0;32m~/anaconda3/envs/python3/lib/python3.8/site-packages/sagemaker/predictor.py\u001b[0m in \u001b[0;36mpredict\u001b[0;34m(self, data, initial_args, target_model, target_variant, inference_id)\u001b[0m\n\u001b[1;32m    159\u001b[0m             \u001b[0mdata\u001b[0m\u001b[0;34m,\u001b[0m \u001b[0minitial_args\u001b[0m\u001b[0;34m,\u001b[0m \u001b[0mtarget_model\u001b[0m\u001b[0;34m,\u001b[0m \u001b[0mtarget_variant\u001b[0m\u001b[0;34m,\u001b[0m \u001b[0minference_id\u001b[0m\u001b[0;34m\u001b[0m\u001b[0;34m\u001b[0m\u001b[0m\n\u001b[1;32m    160\u001b[0m         )\n\u001b[0;32m--> 161\u001b[0;31m         \u001b[0mresponse\u001b[0m \u001b[0;34m=\u001b[0m \u001b[0mself\u001b[0m\u001b[0;34m.\u001b[0m\u001b[0msagemaker_session\u001b[0m\u001b[0;34m.\u001b[0m\u001b[0msagemaker_runtime_client\u001b[0m\u001b[0;34m.\u001b[0m\u001b[0minvoke_endpoint\u001b[0m\u001b[0;34m(\u001b[0m\u001b[0;34m**\u001b[0m\u001b[0mrequest_args\u001b[0m\u001b[0;34m)\u001b[0m\u001b[0;34m\u001b[0m\u001b[0;34m\u001b[0m\u001b[0m\n\u001b[0m\u001b[1;32m    162\u001b[0m         \u001b[0;32mreturn\u001b[0m \u001b[0mself\u001b[0m\u001b[0;34m.\u001b[0m\u001b[0m_handle_response\u001b[0m\u001b[0;34m(\u001b[0m\u001b[0mresponse\u001b[0m\u001b[0;34m)\u001b[0m\u001b[0;34m\u001b[0m\u001b[0;34m\u001b[0m\u001b[0m\n\u001b[1;32m    163\u001b[0m \u001b[0;34m\u001b[0m\u001b[0m\n",
      "\u001b[0;32m~/anaconda3/envs/python3/lib/python3.8/site-packages/botocore/client.py\u001b[0m in \u001b[0;36m_api_call\u001b[0;34m(self, *args, **kwargs)\u001b[0m\n\u001b[1;32m    393\u001b[0m                     \"%s() only accepts keyword arguments.\" % py_operation_name)\n\u001b[1;32m    394\u001b[0m             \u001b[0;31m# The \"self\" in this scope is referring to the BaseClient.\u001b[0m\u001b[0;34m\u001b[0m\u001b[0;34m\u001b[0m\u001b[0;34m\u001b[0m\u001b[0m\n\u001b[0;32m--> 395\u001b[0;31m             \u001b[0;32mreturn\u001b[0m \u001b[0mself\u001b[0m\u001b[0;34m.\u001b[0m\u001b[0m_make_api_call\u001b[0m\u001b[0;34m(\u001b[0m\u001b[0moperation_name\u001b[0m\u001b[0;34m,\u001b[0m \u001b[0mkwargs\u001b[0m\u001b[0;34m)\u001b[0m\u001b[0;34m\u001b[0m\u001b[0;34m\u001b[0m\u001b[0m\n\u001b[0m\u001b[1;32m    396\u001b[0m \u001b[0;34m\u001b[0m\u001b[0m\n\u001b[1;32m    397\u001b[0m         \u001b[0m_api_call\u001b[0m\u001b[0;34m.\u001b[0m\u001b[0m__name__\u001b[0m \u001b[0;34m=\u001b[0m \u001b[0mstr\u001b[0m\u001b[0;34m(\u001b[0m\u001b[0mpy_operation_name\u001b[0m\u001b[0;34m)\u001b[0m\u001b[0;34m\u001b[0m\u001b[0;34m\u001b[0m\u001b[0m\n",
      "\u001b[0;32m~/anaconda3/envs/python3/lib/python3.8/site-packages/botocore/client.py\u001b[0m in \u001b[0;36m_make_api_call\u001b[0;34m(self, operation_name, api_params)\u001b[0m\n\u001b[1;32m    723\u001b[0m             \u001b[0merror_code\u001b[0m \u001b[0;34m=\u001b[0m \u001b[0mparsed_response\u001b[0m\u001b[0;34m.\u001b[0m\u001b[0mget\u001b[0m\u001b[0;34m(\u001b[0m\u001b[0;34m\"Error\"\u001b[0m\u001b[0;34m,\u001b[0m \u001b[0;34m{\u001b[0m\u001b[0;34m}\u001b[0m\u001b[0;34m)\u001b[0m\u001b[0;34m.\u001b[0m\u001b[0mget\u001b[0m\u001b[0;34m(\u001b[0m\u001b[0;34m\"Code\"\u001b[0m\u001b[0;34m)\u001b[0m\u001b[0;34m\u001b[0m\u001b[0;34m\u001b[0m\u001b[0m\n\u001b[1;32m    724\u001b[0m             \u001b[0merror_class\u001b[0m \u001b[0;34m=\u001b[0m \u001b[0mself\u001b[0m\u001b[0;34m.\u001b[0m\u001b[0mexceptions\u001b[0m\u001b[0;34m.\u001b[0m\u001b[0mfrom_code\u001b[0m\u001b[0;34m(\u001b[0m\u001b[0merror_code\u001b[0m\u001b[0;34m)\u001b[0m\u001b[0;34m\u001b[0m\u001b[0;34m\u001b[0m\u001b[0m\n\u001b[0;32m--> 725\u001b[0;31m             \u001b[0;32mraise\u001b[0m \u001b[0merror_class\u001b[0m\u001b[0;34m(\u001b[0m\u001b[0mparsed_response\u001b[0m\u001b[0;34m,\u001b[0m \u001b[0moperation_name\u001b[0m\u001b[0;34m)\u001b[0m\u001b[0;34m\u001b[0m\u001b[0;34m\u001b[0m\u001b[0m\n\u001b[0m\u001b[1;32m    726\u001b[0m         \u001b[0;32melse\u001b[0m\u001b[0;34m:\u001b[0m\u001b[0;34m\u001b[0m\u001b[0;34m\u001b[0m\u001b[0m\n\u001b[1;32m    727\u001b[0m             \u001b[0;32mreturn\u001b[0m \u001b[0mparsed_response\u001b[0m\u001b[0;34m\u001b[0m\u001b[0;34m\u001b[0m\u001b[0m\n",
      "\u001b[0;31mModelError\u001b[0m: An error occurred (ModelError) when calling the InvokeEndpoint operation: Received client error (400) from primary with message \"{\n  \"code\": 400,\n  \"type\": \"InternalServerException\",\n  \"message\": \"\\u0027bloom\\u0027\"\n}\n\". See https://us-east-1.console.aws.amazon.com/cloudwatch/home?region=us-east-1#logEventViewer:group=/aws/sagemaker/Endpoints/huggingface-pytorch-inference-2022-11-10-12-26-04-489 in account 905847418383 for more information."
     ]
    }
   ],
   "source": [
    "data = {\"inputs\": \"And this is where the problem lies\"}\n",
    "\n",
    "predictor.predict(data)"
   ]
  },
  {
   "cell_type": "markdown",
   "id": "6b22948b",
   "metadata": {},
   "source": [
    "This is a typical error message that we will receive when a model is not supported at the `transformers` version that has been used (4.17.0 in our case). We can see in the [release notes](https://github.com/huggingface/transformers/releases/tag/v4.20.0) that BLOOM requires `transformers` version >= 4.20.0"
   ]
  },
  {
   "cell_type": "code",
   "execution_count": null,
   "id": "c67b4254",
   "metadata": {},
   "outputs": [],
   "source": [
    "predictor.delete_endpoint()"
   ]
  }
 ],
 "metadata": {
  "kernelspec": {
   "display_name": "conda_python3",
   "language": "python",
   "name": "conda_python3"
  },
  "language_info": {
   "codemirror_mode": {
    "name": "ipython",
    "version": 3
   },
   "file_extension": ".py",
   "mimetype": "text/x-python",
   "name": "python",
   "nbconvert_exporter": "python",
   "pygments_lexer": "ipython3",
   "version": "3.8.12"
  }
 },
 "nbformat": 4,
 "nbformat_minor": 5
}
